#VRML_SIM R2021a utf8
WorldInfo {
  info [
    "The MyBot robot, the robot used in the tutorial of Webots"
  ]
  title "MyBot"
  coordinateSystem "NUE"
}
Viewpoint {
  orientation -0.08621384360687298 -0.9764174517862765 -0.1979296163228846 2.337332634865713
  position -0.2901801363074328 0.18601813109629728 -0.28736744998110875
}
TexturedBackground {
}
TexturedBackgroundLight {
}
RectangleArena {
}
Robot {
  children [
    DEF WHEELS Transform {
      translation 0 -0.005 0.002
      children [
        HingeJoint {
          jointParameters HingeJointParameters {
            axis -1 0 0
            anchor 0 0.025 0
          }
          device [
            RotationalMotor {
              name "left wheel motor"
              maxVelocity 11
            }
            PositionSensor {
              name "left wheel sensor"
            }
          ]
          endPoint Solid {
            translation -0.045 0.025 0
            rotation -1 0 0 0
            children [
              DEF WHEEL Transform {
                rotation 0 0 1 1.57
                children [
                  Shape {
                    appearance PBRAppearance {
                      baseColor 1 0 0
                      roughness 1
                      metalness 0
                    }
                    geometry Cylinder {
                      height 0.01
                      radius 0.02
                    }
                  }
                ]
              }
            ]
            name "left wheel"
            boundingObject USE WHEEL
          }
        }
        HingeJoint {
          jointParameters HingeJointParameters {
            axis -1 0 0
            anchor 0 0.025 0
          }
          device [
            RotationalMotor {
              name "right wheel motor"
              maxVelocity 11
            }
            PositionSensor {
              name "right wheel sensor"
            }
          ]
          endPoint Solid {
            translation 0.045 0.025 0
            rotation -1 0 0 0
            children [
              DEF WHEEL Transform {
                rotation 0 0 1 1.57
                children [
                  Shape {
                    appearance PBRAppearance {
                      baseColor 1 0 0
                      roughness 1
                      metalness 0
                    }
                    geometry Cylinder {
                      height 0.01
                      radius 0.02
                    }
                  }
                ]
              }
            ]
            name "right wheel"
            boundingObject USE WHEEL
          }
        }
      ]
    }
    DEF BODY Transform {
      translation 0 0.03 -0.028
      children [
        Shape {
          appearance PBRAppearance {
            baseColor 0.0820075 0.364731 0.8
            roughness 1
            metalness 0
          }
          geometry Box {
            size 0.1 0.06 0.1
          }
        }
      ]
    }
    DistanceSensor {
      translation -0.02 0.013 -0.042
      rotation 0 1 0 2.07
      children [
        DEF SENSOR Transform {
          rotation 0 0 1 1.57
          children [
            Shape {
              appearance PBRAppearance {
                baseColor 0.975691 0.981481 0.0252992
                roughness 1
                metalness 0
              }
              geometry Cylinder {
                height 0.004
                radius 0.008
              }
            }
          ]
        }
      ]
      name "ds0"
      lookupTable [
        0 1024 0
        0.05 1024 0
        0.15 0 0
      ]
      numberOfRays 2
      aperture 1
    }
    DistanceSensor {
      translation 0.02 0.013 -0.042
      rotation 0 1 0 1.07
      children [
        USE SENSOR
      ]
      name "ds1"
      lookupTable [
        0 1024 0
        0.05 1024 0
        0.15 0 0
      ]
      numberOfRays 2
      aperture 1
    }
  ]
  name "MyBot"
  boundingObject USE BODY
  controller "1v0-motor-e-sensor-distancia"
}
