#VRML_SIM R2021a utf8
WorldInfo {
  coordinateSystem "NUE"
}
Viewpoint {
  orientation -0.34240457508095146 -0.916001181225832 -0.20904770497786765 1.175794945191239
  position -0.4192448945279657 0.18853254237343672 0.2664612894323199
}
TexturedBackground {
}
TexturedBackgroundLight {
}
CircleArena {
}
Robot {
  translation -4.120946295000395e-18 -0.00215813944062521 -3.887524876135819e-18
  rotation 0.6430026777371401 0.41604700797594696 -0.643002677737138 -8.573574825463106e-17
  children [
    DEF LEFT HingeJoint {
      jointParameters HingeJointParameters {
        position 8.862720000000007
        anchor -0.007 0.014 0.041
      }
      device [
        RotationalMotor {
          name "right-motor"
        }
      ]
      endPoint Solid {
        translation -0.04099999999999994 0.014 0.041
        rotation -0.5773499358549823 0.5773519358547601 -0.5773489358550934 -2.094405307179586
        children [
          DEF WHEEL Shape {
            appearance PBRAppearance {
            }
            geometry Cylinder {
              height 0.02
              radius 0.014
            }
          }
        ]
        boundingObject USE WHEEL
      }
    }
    DEF BODY Transform {
      translation 0 0.022 0
      children [
        Shape {
          appearance PBRAppearance {
            baseColor 0.105882 0.105882 0.160784
          }
          geometry Box {
            size 0.1 0.04 0.1
          }
        }
      ]
    }
  ]
  boundingObject USE BODY
  physics Physics {
  }
  controller "controller"
}
